Workbook

Sheet Dashboard
A1: BIDSHIELD IMPLEMENTATION DASHBOARD
A3: Total Items | B3: Done | C3: In Progress | D3: Not Started | E3: Critical Open | F3: Total Hours
A4: =COUNTA('Fix Tracker'!A5:A67) -> 63 | B4: =COUNTIF('Fix Tracker'!E5:E67,"Done") -> 2 | C4: =COUNTIF('Fix Tracker'!E5:E67,"In Progress") -> 0 | D4: =COUNTIF('Fix Tracker'!E5:E67,"Not Started") -> 61 | E4: =COUNTIFS('Fix Tracker'!D5:D67,"CRITICAL",'Fix Tracker'!E5:E67,"<>Done") -> 12 | F4: =SUM('Fix Tracker'!G5:G67) -> 264
A7: BY SEVERITY
A8: Severity | B8: Total | C8: Done | D8: Remaining | E8: % Complete
A9: CRITICAL | B9: =COUNTIF('Fix Tracker'!D5:D67,"CRITICAL") -> 14 | C9: =COUNTIFS('Fix Tracker'!D5:D67,"CRITICAL",'Fix Tracker'!E5:E67,"Done") -> 2 | D9: =B9-C9 -> 12 | E9: =IF(B9>0,C9/B9,0) -> 0.14285714
A10: HIGH | B10: =COUNTIF('Fix Tracker'!D5:D67,"HIGH") -> 25 | C10: =COUNTIFS('Fix Tracker'!D5:D67,"HIGH",'Fix Tracker'!E5:E67,"Done") -> 0 | D10: =B10-C10 -> 25 | E10: =IF(B10>0,C10/B10,0) -> 0
A11: MEDIUM | B11: =COUNTIF('Fix Tracker'!D5:D67,"MEDIUM") -> 24 | C11: =COUNTIFS('Fix Tracker'!D5:D67,"MEDIUM",'Fix Tracker'!E5:E67,"Done") -> 0 | D11: =B11-C11 -> 24 | E11: =IF(B11>0,C11/B11,0) -> 0
A14: BY SPRINT
A15: Sprint | B15: Items | C15: Done | D15: Hours | E15: % Complete
A16: Sprint 0 (Now) | B16: =COUNTIF('Fix Tracker'!F5:F67,"Sprint 0 (Now)") -> 5 | C16: =COUNTIFS('Fix Tracker'!F5:F67,"Sprint 0 (Now)",'Fix Tracker'!E5:E67,"Done") -> 2 | D16: =SUMIF('Fix Tracker'!F5:F67,"Sprint 0 (Now)",'Fix Tracker'!G5:G67) -> 5 | E16: =IF(B16>0,C16/B16,0) -> 0.4
A17: Sprint 1 | B17: =COUNTIF('Fix Tracker'!F5:F67,"Sprint 1") -> 19 | C17: =COUNTIFS('Fix Tracker'!F5:F67,"Sprint 1",'Fix Tracker'!E5:E67,"Done") -> 0 | D17: =SUMIF('Fix Tracker'!F5:F67,"Sprint 1",'Fix Tracker'!G5:G67) -> 69 | E17: =IF(B17>0,C17/B17,0) -> 0
A18: Sprint 2 | B18: =COUNTIF('Fix Tracker'!F5:F67,"Sprint 2") -> 13 | C18: =COUNTIFS('Fix Tracker'!F5:F67,"Sprint 2",'Fix Tracker'!E5:E67,"Done") -> 0 | D18: =SUMIF('Fix Tracker'!F5:F67,"Sprint 2",'Fix Tracker'!G5:G67) -> 93 | E18: =IF(B18>0,C18/B18,0) -> 0
A19: Sprint 3 | B19: =COUNTIF('Fix Tracker'!F5:F67,"Sprint 3") -> 18 | C19: =COUNTIFS('Fix Tracker'!F5:F67,"Sprint 3",'Fix Tracker'!E5:E67,"Done") -> 0 | D19: =SUMIF('Fix Tracker'!F5:F67,"Sprint 3",'Fix Tracker'!G5:G67) -> 65 | E19: =IF(B19>0,C19/B19,0) -> 0
A20: Sprint 4 | B20: =COUNTIF('Fix Tracker'!F5:F67,"Sprint 4") -> 4 | C20: =COUNTIFS('Fix Tracker'!F5:F67,"Sprint 4",'Fix Tracker'!E5:E67,"Done") -> 0 | D20: =SUMIF('Fix Tracker'!F5:F67,"Sprint 4",'Fix Tracker'!G5:G67) -> 16 | E20: =IF(B20>0,C20/B20,0) -> 0
A21: Backlog | B21: =COUNTIF('Fix Tracker'!F5:F67,"Backlog") -> 4 | C21: =COUNTIFS('Fix Tracker'!F5:F67,"Backlog",'Fix Tracker'!E5:E67,"Done") -> 0 | D21: =SUMIF('Fix Tracker'!F5:F67,"Backlog",'Fix Tracker'!G5:G67) -> 16 | E21: =IF(B21>0,C21/B21,0) -> 0

Sheet Fix Tracker
A1: BIDSHIELD MASTER FIX TRACKER
A2: All audit findings + AI roadmap items | Updated April 2026
A4: ID | B4: Finding | C4: Component/Tab | D4: Severity | E4: Status | F4: Sprint | G4: Effort (hrs) | H4: Depends On | I4: Fix Description | J4: Files to Change | K4: Notes
A5: S1 | B5: Exposed secrets in version control | C5: Security | D5: CRITICAL | E5: Not Started | F5: Sprint 0 (Now) | G5: 1 | H5: None | I5: Remove .env files from git history, rotate ALL keys (Clerk, Anthropic, Stripe, HeyGen), add .env* to .gitignore | J5: .env.local, .env.production.local, .gitignore | K5: DONE if already rotated — verify
A6: S2 | B6: Duplicate Stripe webhook endpoints | C6: Security | D6: CRITICAL | E6: Not Started | F6: Sprint 0 (Now) | G6: 2 | H6: None | I6: Consolidate to single webhook handler, remove duplicate endpoint, verify Stripe dashboard has one URL | J6: api/bidshield/webhook, api/webhooks/stripe | K6: Check Stripe dashboard
A7: C1 | B7: Zero test coverage → 259 tests added | C7: Testing | D7: CRITICAL | E7: Done | F7: Sprint 0 (Now) | G7: 0 | H7: None | I7: COMPLETED: 9 test files, 259 tests covering roundCurrency, bidScore, scopePricingConflicts, utils, rateLimit, checklist-data, material-templates, scope-defaults | J7: __tests__/* | K7: DONE — keep expanding
A8: M1 | B8: 3,098-line monolith split into modules | C8: Maintainability | D8: CRITICAL | E8: Done | F8: Sprint 0 (Now) | G8: 0 | H8: None | I8: COMPLETED: Split into 21 module files under convex/bidshield/ with re-exports maintaining API compatibility | J8: convex/bidshield.ts, convex/bidshield/* | K8: DONE — deployed to Convex
A9: E-04 | B9: No critical-phase enforcement at submission | C9: Checklist | D9: CRITICAL | E9: Not Started | F9: Sprint 1 | G9: 4 | H9: E-26 | I9: Add phase completion gates: require Scope Boundaries, Pricing, Labor phases > 80% before submission is enabled | J9: convex/bidshield/checklist.ts, SubmissionTab or Validator
A10: E-06 | B10: No scope-to-pricing flow | C10: Scope | D10: CRITICAL | E10: Not Started | F10: Sprint 2 | G10: 8 | H10: None | I10: When scope items marked 'included', auto-create pricing line items. Add sync mutation that reads scope status and creates/updates pricing entries | J10: convex/bidshield/scope.ts, PricingTab.tsx | K10: Core tab-sync issue
A11: E-09 | B11: Addendum price impact not linked to Pricing | C11: Addenda | D11: CRITICAL | E11: Not Started | F11: Sprint 2 | G11: 6 | H11: E-06 | I11: Wire addendum price impacts to the actual bid total. When addendum flags +$4,500, that should flow into pricing as an adjustment line item | J11: convex/bidshield/addenda.ts, pricing logic
A12: E-13 | B12: Takeoff quantities don't flow to Materials | C12: Takeoff | D12: CRITICAL | E12: Not Started | F12: Sprint 2 | G12: 8 | H12: None | I12: Create sync: takeoff total SF/LF/EA per section → material quantity calculation using coverage rates. This is the #1 workflow gap | J12: convex/bidshield/takeoff.ts, materials.ts, MaterialsTab.tsx | K12: Biggest estimator pain point
A13: E-19 | B13: Labor total not synced to Pricing | C13: Labor | D13: CRITICAL | E13: Not Started | F13: Sprint 2 | G13: 4 | H13: None | I13: Single source of truth: labor tab calculates total → pricing tab reads it. Remove independent laborCost field from pricing or make it read-only computed | J13: convex/bidshield/labor.ts, PricingTab.tsx | K13: Conflicting numbers = bid errors
A14: E-26 | B14: Validator doesn't block submission | C14: Validator | D14: CRITICAL | E14: Not Started | F14: Sprint 1 | G14: 4 | H14: None | I14: Add submission gate: if bid score < threshold (configurable, default 85%), disable submit button with clear message showing what needs fixing | J14: SubmissionTab.tsx, convex/bidshield/submissions.ts
A15: E-27 | B15: Component reconciliation is advisory only | C15: Validator | D15: CRITICAL | E15: Not Started | F15: Sprint 1 | G15: 6 | H15: E-26 | I15: Make reconciliation blocking: if Material + Labor + GC differs from Total Bid by > 2%, require estimator acknowledgment before submission | J15: Validator logic, SubmissionTab.tsx
A16: S3 | B16: CSP allows unsafe-inline/unsafe-eval | C16: Security | D16: HIGH | E16: Not Started | F16: Sprint 1 | G16: 3 | H16: None | I16: Tighten Content-Security-Policy in vercel.json: remove unsafe-inline, add nonce-based script loading | J16: vercel.json, next.config.js
A17: S4 | B17: Unauthenticated checkout endpoints | C17: Security | D17: HIGH | E17: Not Started | F17: Sprint 0 (Now) | G17: 2 | H17: None | I17: Add Clerk auth check to checkout API routes. Reject requests without valid session | J17: api/checkout/* | K17: Revenue protection
A18: S5 | B18: Missing CSRF protection on mutations | C18: Security | D18: HIGH | E18: Not Started | F18: Sprint 1 | G18: 4 | H18: None | I18: Add CSRF token validation to all POST endpoints in api/bidshield/* | J18: api/bidshield/*, middleware
A19: P1 | B19: N+1 RFI queries in getStats | C19: Performance | D19: HIGH | E19: Not Started | F19: Sprint 1 | G19: 2 | H19: M1 | I19: Batch RFI count query: single query with projectId filter instead of per-project loop | J19: convex/bidshield/stats.ts | K19: DONE if module split fixed this — verify
A20: C2 | B20: Floating-point arithmetic in pricing | C20: Correctness | D20: HIGH | E20: Not Started | F20: Sprint 1 | G20: 3 | H20: None | I20: Apply roundCurrency() to all financial calculations. Helper already exists in _helpers.ts | J20: convex/bidshield/_helpers.ts, materials.ts, labor.ts, pricing logic | K20: roundCurrency built
A21: E-01 | B21: Assembly areas don't validate against gross roof area | C21: Setup | D21: HIGH | E21: Not Started | F21: Sprint 1 | G21: 2 | H21: None | I21: Add validation: sum of assembly areas vs gross roof area. Show warning banner if delta > 5% | J21: SetupTab.tsx
A22: E-07 | B22: No bulk status operations for scope | C22: Scope | D22: HIGH | E22: Not Started | F22: Sprint 3 | G22: 3 | H22: None | I22: Add multi-select + bulk status change (mark 5 items 'by_others' at once) | J22: ScopeTab.tsx, convex/bidshield/scope.ts
A23: E-10 | B23: No 'Go Reprice' action from addendum | C23: Addenda | D23: HIGH | E23: Not Started | F23: Sprint 3 | G23: 2 | H23: E-09 | I23: Add button on addendum items that navigates to the affected pricing/material line item | J23: AddendaTab.tsx | K23: UX improvement
A24: E-11 | B24: No RFI response deadline tracking | C24: RFIs | D24: HIGH | E24: Not Started | F24: Sprint 3 | G24: 3 | H24: None | I24: Add responseDeadline field, show overdue RFIs with visual indicator, optional notification | J24: convex/bidshield/rfis.ts, RFIsTab.tsx
A25: E-14 | B25: No reconciliation between section areas and gross roof area | C25: Takeoff | D25: HIGH | E25: Not Started | F25: Sprint 2 | G25: 2 | H25: E-13 | I25: Show running total of takeoff areas vs gross area with visual delta indicator | J25: TakeoffTab.tsx
A26: E-16 | B26: Quote-to-material matching is manual | C26: Materials | D26: HIGH | E26: Not Started | F26: Sprint 2 | G26: 4 | H26: None | I26: Auto-run fuzzy matching when new quote is added. Show match confidence. Already have matching logic — need to trigger it automatically | J26: MaterialsTab.tsx, quote matching logic | K26: Fuzzy matching exists at 70% threshold
A27: E-17 | B27: No waste factor validation | C27: Materials | D27: HIGH | E27: Not Started | F27: Sprint 1 | G27: 2 | H27: None | I27: Add range validation: warn if waste < 3% or > 25%. Show industry standard ranges by category | J27: MaterialsTab.tsx, convex/bidshield/materials.ts
A28: E-20 | B28: AI labor assumptions not actionable | C28: Labor | D28: HIGH | E28: Not Started | F28: Sprint 3 | G28: 4 | H28: None | I28: Add drill-down: click AI assumption → see calculation breakdown, edit individual factors | J28: LaborTab.tsx
A29: E-21 | B29: Unverified labor tasks don't block submission | C29: Labor | D29: HIGH | E29: Not Started | F29: Sprint 2 | G29: 2 | H29: E-26 | I29: Add 'verified' checkbox per labor task. Unverified AI tasks count against bid score | J29: LaborTab.tsx, convex/bidshield/labor.ts
A30: E-24 | B30: PDF extraction failure is silent | C30: Quotes | D30: HIGH | E30: Not Started | F30: Sprint 1 | G30: 2 | H30: None | I30: Show clear error toast when PDF extraction returns empty or fails. Offer manual entry fallback | J30: MaterialsTab.tsx, QuotesTab.tsx
A31: E-28 | B31: Score doesn't weight critical phases | C31: Validator | D31: HIGH | E31: Not Started | F31: Sprint 2 | G31: 3 | H31: E-26 | I31: Add weighted scoring: Scope/Pricing/Labor/Quotes phases worth 2x. Adjust bid score formula | J31: lib/bidshield/bid-score.ts
A32: E-30 | B32: Decision Log has no UI entry points | C32: Cross-Cutting | D32: HIGH | E32: Not Started | F32: Sprint 3 | G32: 3 | H32: None | I32: Add 'Log Decision' button accessible from all tabs. Quick-entry modal for logging rationale | J32: DecisionLog component, all tabs
A33: E-31 | B33: No audit trail for bid amount changes | C33: Cross-Cutting | D33: HIGH | E33: Not Started | F33: Sprint 3 | G33: 4 | H33: None | I33: Log every bid total change with timestamp, old value, new value, source (which tab/action caused it) | J33: convex/bidshield/decisions.ts or new audit table
A34: E-33 | B34: No CSV/Excel export from analytics | C34: Analytics | D34: HIGH | E34: Not Started | F34: Sprint 4 | G34: 3 | H34: None | I34: Add export buttons on analytics dashboard. CSV for data, PDF for reports | J34: AnalyticsTab.tsx
A35: E-34 | B35: PDF export is bid-day reference only | C35: Analytics | D35: HIGH | E35: Not Started | F35: Sprint 4 | G35: 6 | H35: None | I35: Expand PDF export to full bid package: cover sheet, scope, material list, pricing breakdown, exclusions, qualifications | J35: PDF generation logic
A36: P2 | B36: Sequential deletes in deleteProject | C36: Performance | D36: MEDIUM | E36: Not Started | F36: Sprint 3 | G36: 2 | H36: None | I36: Use Promise.all for parallel deletes across tables | J36: convex/bidshield/projects.ts
A37: P3 | B37: Full table scan in quote upserting | C37: Performance | D37: MEDIUM | E37: Not Started | F37: Sprint 3 | G37: 3 | H37: P5 | I37: Use compound index lookup instead of loading all datasheets for fuzzy match | J37: convex/bidshield/datasheets.ts
A38: P4 | B38: Waterfall query loading on dashboard | C38: Performance | D38: MEDIUM | E38: Not Started | F38: Sprint 3 | G38: 2 | H38: None | I38: Combine sequential useQuery calls or use Convex's query batching | J38: BidQualsTab.tsx
A39: P5 | B39: Missing compound database indexes | C39: Performance | D39: MEDIUM | E39: Not Started | F39: Sprint 1 | G39: 1 | H39: None | I39: PARTIALLY DONE: Added 3 indexes in module split. Review remaining query patterns for missing indexes | J39: convex/schema.ts | K39: 3 indexes added — check for more
A40: C3 | B40: Race condition in labor task updates | C40: Correctness | D40: MEDIUM | E40: Not Started | F40: Sprint 3 | G40: 3 | H40: None | I40: Use optimistic concurrency: include version field, reject updates with stale version | J40: convex/bidshield/labor.ts
A41: C4 | B41: Webhook duplicate processing risk | C41: Correctness | D41: MEDIUM | E41: Not Started | F41: Sprint 1 | G41: 2 | H41: S2 | I41: Add idempotency key tracking: store processed Stripe event IDs, skip duplicates | J41: api/webhooks/stripe/route.ts
...

Sheet Sprint Plan
A1: SPRINT BREAKDOWN
A3: Sprint | B3: Focus | C3: Key Deliverables | D3: Est. Hours | E3: Dependencies | F3: Go-Live Risk
A4: Sprint 0 (NOW) | B4: Security + Already Done | C4: S1: Rotate exposed secrets S2: Fix duplicate webhooks S4: Auth checkout endpoints C1: 259 tests (DONE) M1: Module split (DONE) Assembly wizard fix (DONE) | D4: 5 | E4: None | F4: ZERO
A5: Sprint 1 (Week 1-2) | B5: Foundation + Guardrails | C5: AI-02: Spec requirements DB table AI-01: extract-specifications endpoint AI-04: Zoning area auto-populate E-26: Submission threshold gate E-27: Component reconciliation blocking E-04: Critical phase enforcement Quick fixes: E-02, E-03, E-05, C5, P5, E-17, E-24 | D5: ~52 | E5: None | F5: LOW New features only
A6: Sprint 2 (Week 3-4) | B6: Tab Sync + Spec Dashboard | C6: AI-03: Spec Material Dashboard UI AI-05: Wizard post-creation auto-init AI-08: Tab cross-communication wiring E-13: Takeoff → Materials flow (CRITICAL) E-19: Labor → Pricing sync (CRITICAL) E-06: Scope → Pricing flow E-09: Addendum → Pricing link | D6: ~80 | E6: Sprint 1 endpoints | F6: LOW-MED New connections
A7: Sprint 3 (Week 5-6) | B7: GC Processing + Polish | C7: AI-06: GC Exhibit A pricing checklist AI-07: EDGE quantity comparison E-07: Bulk scope operations E-10, E-11: Addenda/RFI improvements E-20, E-30, E-31: Labor/Decision UX Performance: P2, P3, P4, C3 | D7: ~60 | E7: Sprint 2 tab sync | F7: LOW Enhancements
A8: Sprint 4 (Week 7-8) | B8: Analytics + Export | C8: E-33: CSV/Excel export E-34: Full bid package PDF E-23: Frozen base for change orders E-35: Bid accuracy drill-down M4, M5: Config cleanup + docs | D8: ~30 | E8: None | F8: ZERO Reporting only
A9: Backlog | B9: Future / Low Priority | C9: E-29: GC portal integration E-32: Demo mode cleanup M4: Hardcoded config values M5: Inline documentation | D9: ~16 | E9: None | F9: ZERO

Sheet Deploy Strategy
A1: DEPLOYMENT STRATEGY — SAFE UPDATES ON A LIVE SITE
A2: Vercel (frontend) + Convex (backend) | Auto-deploy from git push
A4: 1. GIT BRANCHING STRATEGY
A5: Branch | B5: Purpose | C5: Deploys To | D5: Who Pushes | E5: Auto-Deploy? | F5: Notes
A6: main | B6: Production code — what users see | C6: Vercel Production + Convex Production | D6: Merge PRs only | E6: YES | F6: NEVER push directly. Always merge from dev via PR
A7: dev | B7: Integration branch — all features merge here first | C7: Vercel Preview URL | D7: You | E7: YES | F7: Test everything here before merging to main
A8: feature/* | B8: Individual fixes (feature/fix-e13-takeoff-sync) | C8: Vercel Preview URL | D8: You | E8: YES | F8: One branch per fix or feature. Branch from dev
A9: hotfix/* | B9: Emergency production fixes only | C9: Vercel Production (fast-track) | D9: You | E9: After merge to main | F9: Branch from main, merge to BOTH main and dev
A12: 2. PRE-DEPLOY CHECKLIST (before every merge to main)
A13: Step | B13: Action | C13: Command / How | D13: If It Fails | E13: Required? | F13: Notes
A14: 1 | B14: Run all tests | C14: npm run test | D14: Fix failing tests before proceeding | E14: YES | F14: 259 tests must pass
A15: 2 | B15: TypeScript type check | C15: npx tsc --noEmit | D15: Fix type errors | E15: YES | F15: Catches null/undefined bugs
A16: 3 | B16: Build locally | C16: npm run build | D16: Fix build errors | E16: YES | F16: Catches import issues
A17: 4 | B17: Test Convex functions | C17: npx convex dev (check console) | D17: Fix Convex validation errors | E17: YES | F17: Catches schema mismatches
A18: 5 | B18: Preview deploy (Vercel) | C18: Push to dev branch → check preview URL | D18: Fix in feature branch, re-push | E18: YES | F18: Vercel auto-creates preview
A19: 6 | B19: Manual smoke test | C19: Open preview URL, create project, upload PDF, check all tabs | D19: Fix issues found | E19: YES | F19: 5-min walkthrough of core flow
A20: 7 | B20: Deploy Convex production | C20: npx convex deploy | D20: Check error, fix schema/function issues | E20: YES | F20: BEFORE merging to main if schema changed
A21: 8 | B21: Merge to main | C21: PR from dev → main on GitHub | D21: Revert if Vercel deploy fails | E21: YES | F21: Triggers Vercel production deploy
A22: 9 | B22: Post-deploy verify | C22: Check production URL, verify core flow works | D22: Revert: git revert HEAD on main | E22: YES | F22: 2-min smoke test on live site
A25: 3. CONVEX DEPLOYMENT — CRITICAL GOTCHAS
A26: Scenario | B26: What Happens | C26: Safe Approach | D26: Danger Level
A27: Adding new table | B27: No risk — existing data untouched | C27: Just add to schema.ts and deploy | D27: SAFE
A28: Adding new field to existing table | B28: Old rows won't have the field | C28: Use v.optional() for new fields. Code must handle undefined | D28: LOW
A29: Removing a field from schema | B29: Existing data still has the field but schema rejects it | C29: DON'T remove fields — mark as deprecated with v.optional(). Remove data first if needed | D29: HIGH
A30: Renaming a table | B30: Old table deleted, new one empty | C30: Create new table, migrate data, then remove old table in separate deploy | D30: CRITICAL
A31: Adding a new index | B31: Index builds in background | C31: Safe — just deploy. May take a few seconds for large tables | D31: SAFE
A32: Changing a field type (e.g., string → number) | B32: Existing data has old type, new code expects new type | C32: Add new field with new type, migrate data, remove old field later | D32: CRITICAL
A33: Frontend + Convex schema change together | B33: If Vercel deploys before Convex, frontend calls fail | C33: Deploy Convex FIRST (npx convex deploy), THEN merge to main for Vercel | D33: HIGH
A36: 4. ROLLBACK PROCEDURES — WHEN THINGS GO WRONG
A37: Problem | B37: How You'll Know | C37: Fix | D37: Time to Fix
A38: Vercel deploy broke the site | B38: Preview URL shows error or blank page | C38: Go to Vercel dashboard → Deployments → click '...' on previous deploy → 'Promote to Production'. Instant rollback. | D38: 30 seconds
A39: Convex function errors after deploy | B39: Users see errors, Convex dashboard shows function failures | C39: Run: npx convex deploy --cmd 'git stash' from the last working commit. Or revert git commit and redeploy. | D39: 2-5 minutes
A40: Schema migration broke data | B40: Convex dashboard shows validation errors on existing documents | C40: Fix schema to be backward-compatible (add v.optional). Never remove fields from live tables. | D40: 5-10 minutes
A41: Both frontend + backend broken | B41: Nothing works | C41: 1. Vercel: promote previous deploy. 2. Convex: redeploy from previous commit. 3. Fix in feature branch. | D41: 5-10 minutes
A42: Stripe webhooks failing | B42: Stripe dashboard shows failed webhook deliveries | C42: Check Stripe webhook logs for error details. Fix handler. Stripe auto-retries for up to 72 hours. | D42: Varies
